Workbook
Name Oushan_Jayasinghe: '[1]OB '!$A$15:$X$234

Sheet OB
C1: CONCORD APPAREL (PVT) LTD.
C2: AVISSAWELLA| SRI LANKA
C3: TEL : 0704888491
C4: OPERATION BULLETIN
A6: STYLE NO | B6: - | C6: USTRO 037 | D6: I E DEPARTMENT
A7: ITEM | B7: - | C7: PANT
A8: CLIENT | B8: - | C8: US POLO | L8: LAST UPDATE :- | M8: 45698
A9: LINE NO | B9: - | C9: 1
A11: GSD | B11: NO | C11: OPERATION | D11: GSD OP CODE | E11: M/C TYPE | F11: SMV | G11: MC SMV | I11: HLP SMV | J11: TOTAL SMV | K11: TARGET | N11: M/ LEVEL
A12: CODE REF | K12: 1 | L12: 0.8 | M12: 0.5
C13: FRONT PKT BAG IN SIDE COIN PKT *1
B15: 1 | C15: IN SIDE COIN PKT HEM *1 | E15: SN | G15: 0.2 | K15: =IF((G15+I15)>0,60/(G15+I15),0) -> 300 | L15: =IF((G15+I15)>0,60/(G15+I15),0)*$L$12 -> 240 | M15: =IF((G15+I15)>0,60/(G15+I15),0)*$M$12 -> 150
B16: 2 | C16: IN SIDE COIN PKT ATTACH *1 | E16: SN | G16: 0.28 | K16: =IF((G16+I16)>0,60/(G16+I16),0) -> 214.28571 | L16: =IF((G16+I16)>0,60/(G16+I16),0)*$L$12 -> 171.42857 | M16: =IF((G16+I16)>0,60/(G16+I16),0)*$M$12 -> 107.14286
C18: FRONT SIDE ZIPPER PKT *1
B20: 3 | C20: SIDE ZIPPER EDEG TACK *2 | E20: SN | G20: 0.16 | K20: =IF((G20+I20)>0,60/(G20+I20),0) -> 375 | L20: =IF((G20+I20)>0,60/(G20+I20),0)*$L$12 -> 300 | M20: =IF((G20+I20)>0,60/(G20+I20),0)*$M$12 -> 187.5
B21: 4 | C21: SIDE ZIPPER PKT BAG FACIN ATTACH *1 | E21: SN | G21: 0.22 | K21: =IF((G21+I21)>0,60/(G21+I21),0) -> 272.72727 | L21: =IF((G21+I21)>0,60/(G21+I21),0)*$L$12 -> 218.18182 | M21: =IF((G21+I21)>0,60/(G21+I21),0)*$M$12 -> 136.36364
B22: 5 | C22: SIDE ZIPPER PKT FACINA ATTACH TO ZIPPER *1 | E22: SN | G22: 0.38 | K22: =IF((G22+I22)>0,60/(G22+I22),0) -> 157.89474 | L22: =IF((G22+I22)>0,60/(G22+I22),0)*$L$12 -> 126.31579 | M22: =IF((G22+I22)>0,60/(G22+I22),0)*$M$12 -> 78.947368
B23: 6 | C23: FRONT PKT BAG ATTACH TO SIDE ZIPPER EDGE *1 | E23: SN | G23: 0.44 | K23: =IF((G23+I23)>0,60/(G23+I23),0) -> 136.36364 | L23: =IF((G23+I23)>0,60/(G23+I23),0)*$L$12 -> 109.09091 | M23: =IF((G23+I23)>0,60/(G23+I23),0)*$M$12 -> 68.181818
B24: 7 | C24: SIDE ZIPPER PKT BAG FACIN CLOSE *1 | E24: SN | G24: 0.24 | K24: =IF((G24+I24)>0,60/(G24+I24),0) -> 250 | L24: =IF((G24+I24)>0,60/(G24+I24),0)*$L$12 -> 200 | M24: =IF((G24+I24)>0,60/(G24+I24),0)*$M$12 -> 125
C26: FRONT PKT *2
B28: 8 | C28: FRONT PKT BAG TOP & BTM JOIN *4 | E28: 5OL | G28: 0.58 | K28: =IF((G28+I28)>0,60/(G28+I28),0) -> 103.44828 | L28: =IF((G28+I28)>0,60/(G28+I28),0)*$L$12 -> 82.758621 | M28: =IF((G28+I28)>0,60/(G28+I28),0)*$M$12 -> 51.724138
B29: 9 | C29: FRONT PKT MOUTH FACIN ATTACH *2 | E29: SN | G29: 0.4 | H29: 0.2 | K29: =IF((G29+I29)>0,60/(G29+I29),0) -> 150 | L29: =IF((G29+I29)>0,60/(G29+I29),0)*$L$12 -> 120 | M29: =IF((G29+I29)>0,60/(G29+I29),0)*$M$12 -> 75 | N29: =($G29+$I29)/$L$135 -> 0.63717096
B30: 10 | C30: FRONT PKT BAG FACIN ATTACH *2 | E30: SN | G30: 0.44 | K30: =IF((G30+I30)>0,60/(G30+I30),0) -> 136.36364 | L30: =IF((G30+I30)>0,60/(G30+I30),0)*$L$12 -> 109.09091 | M30: =IF((G30+I30)>0,60/(G30+I30),0)*$M$12 -> 68.181818 | N30: =($G30+$I30)/$L$135 -> 0.70088806
B31: 11 | C31: FRONT PKT BAG ATTACH TO PKT MOUTH *2 | E31: SN | G31: 0.52 | K31: =IF((G31+I31)>0,60/(G31+I31),0) -> 115.38462 | L31: =IF((G31+I31)>0,60/(G31+I31),0)*$L$12 -> 92.307692 | M31: =IF((G31+I31)>0,60/(G31+I31),0)*$M$12 -> 57.692308 | N31: =($G31+$I31)/$L$135 -> 0.82832225
B32: 12 | C32: FRONT PKT MOUTH STRY STTICH *2 | E32: SN | G32: 0.46 | K32: =IF((G32+I32)>0,60/(G32+I32),0) -> 130.43478 | L32: =IF((G32+I32)>0,60/(G32+I32),0)*$L$12 -> 104.34783 | M32: =IF((G32+I32)>0,60/(G32+I32),0)*$M$12 -> 65.217391 | N32: =($G32+$I32)/$L$135 -> 0.73274661
B33: 13 | C33: FRONT PKT BAG CLOSE WITH TRUN *2 | E33: 3OL | G33: 0.67 | K33: =IF((G33+I33)>0,60/(G33+I33),0) -> 89.552239 | L33: =IF((G33+I33)>0,60/(G33+I33),0)*$L$12 -> 71.641791 | M33: =IF((G33+I33)>0,60/(G33+I33),0)*$M$12 -> 44.776119 | N33: =($G33+$I33)/$L$135 -> 1.0672614
B34: 14 | C34: FRONT PKT BAG TST *2 | E34: SN | G34: 0.82 | K34: =IF((G34+I34)>0,60/(G34+I34),0) -> 73.170732 | L34: =IF((G34+I34)>0,60/(G34+I34),0)*$L$12 -> 58.536585 | M34: =IF((G34+I34)>0,60/(G34+I34),0)*$M$12 -> 36.585366 | N34: =($G34+$I34)/$L$135 -> 1.3062005
B35: 15 | C35: FRONT PKT BAG TACK TO SS & WB *2 | E35: SN | G35: 0.54 | K35: =IF((G35+I35)>0,60/(G35+I35),0) -> 111.11111 | L35: =IF((G35+I35)>0,60/(G35+I35),0)*$L$12 -> 88.888889 | M35: =IF((G35+I35)>0,60/(G35+I35),0)*$M$12 -> 55.555556 | N35: =($G35+$I35)/$L$135 -> 0.8601808
B36: 16 | C36: FRONT WAIST IN SIDE TAPE TACK *2 | E36: SN | G36: 0.26 | K36: =IF((G36+I36)>0,60/(G36+I36),0) -> 230.76923 | L36: =IF((G36+I36)>0,60/(G36+I36),0)*$L$12 -> 184.61538 | M36: =IF((G36+I36)>0,60/(G36+I36),0)*$M$12 -> 115.38462 | N36: =($G36+$I36)/$L$135 -> 0.41416112
B37: 17 | C37: FRONT PKT MOUTH BTK *4 | E37: BTK | G37: 0.24 | K37: =IF((G37+I37)>0,60/(G37+I37),0) -> 250 | L37: =IF((G37+I37)>0,60/(G37+I37),0)*$L$12 -> 200 | M37: =IF((G37+I37)>0,60/(G37+I37),0)*$M$12 -> 125 | N37: =($G37+$I37)/$L$135 -> 0.38230258
B38: 18 | C38: FRONT SIDE EDGE OL *1 | E38: 3OL | G38: 0.2 | K38: =IF((G38+I38)>0,60/(G38+I38),0) -> 300 | L38: =IF((G38+I38)>0,60/(G38+I38),0)*$L$12 -> 240 | M38: =IF((G38+I38)>0,60/(G38+I38),0)*$M$12 -> 150 | N38: =($G38+$I38)/$L$135 -> 0.31858548
H39: 1.1 | N39: =($G39+$I39)/$L$135 -> 0
C40: FRONT | H40: 0.67 | N40: =($G40+$I40)/$L$135 -> 0
B42: 19 | C42: FLY FACIN EDGE OL *1 | E42: 3OL | G42: 0.15 | H42: 0.4 | K42: =IF((G42+I42)>0,60/(G42+I42),0) -> 400 | L42: =IF((G42+I42)>0,60/(G42+I42),0)*$L$12 -> 320 | M42: =IF((G42+I42)>0,60/(G42+I42),0)*$M$12 -> 200 | N42: =($G42+$I42)/$L$135 -> 0.23893911
B43: 20 | C43: FLY BOX EDGE OL *1 | E43: 3OL | G43: 0.12 | H43: 0.46 | K43: =IF((G43+I43)>0,60/(G43+I43),0) -> 500 | L43: =IF((G43+I43)>0,60/(G43+I43),0)*$L$12 -> 400 | M43: =IF((G43+I43)>0,60/(G43+I43),0)*$M$12 -> 250 | N43: =($G43+$I43)/$L$135 -> 0.19115129
B44: 21 | C44: FLY BOX EDGE RUN STTICH *1 | E44: SN | G44: 0.22 | K44: =IF((G44+I44)>0,60/(G44+I44),0) -> 272.72727 | L44: =IF((G44+I44)>0,60/(G44+I44),0)*$L$12 -> 218.18182 | M44: =IF((G44+I44)>0,60/(G44+I44),0)*$M$12 -> 136.36364 | N44: =($G44+$I44)/$L$135 -> 0.35044403
B45: 22 | C45: FLY BOX LABEL ATTACH *1 | E45: SN | G45: 0.3 | K45: =IF((G45+I45)>0,60/(G45+I45),0) -> 200 | L45: =IF((G45+I45)>0,60/(G45+I45),0)*$L$12 -> 160 | M45: =IF((G45+I45)>0,60/(G45+I45),0)*$M$12 -> 100 | N45: =($G45+$I45)/$L$135 -> 0.47787822
B46: 23 | C46: FRONT EDGE OL WITH FLY FACING *2 | E46: 3OL | G46: 0.281 | H46: 0.56 | K46: =IF((G46+I46)>0,60/(G46+I46),0) -> 213.52313 | L46: =IF((G46+I46)>0,60/(G46+I46),0)*$L$12 -> 170.81851 | M46: =IF((G46+I46)>0,60/(G46+I46),0)*$M$12 -> 106.76157 | N46: =($G46+$I46)/$L$135 -> 0.4476126
B47: 24 | C47: FRONT EDGE STRY STTICH *1 | E47: SN | G47: 0.23 | H47: 0.6 | K47: =IF((G47+I47)>0,60/(G47+I47),0) -> 260.86957 | L47: =IF((G47+I47)>0,60/(G47+I47),0)*$L$12 -> 208.69565 | M47: =IF((G47+I47)>0,60/(G47+I47),0)*$M$12 -> 130.43478 | N47: =($G47+$I47)/$L$135 -> 0.3663733
B48: 25 | C48: ZIPPER ATTACH TO FLY FACING *1 | E48: SN | G48: 0.2 | K48: =IF((G48+I48)>0,60/(G48+I48),0) -> 300 | L48: =IF((G48+I48)>0,60/(G48+I48),0)*$L$12 -> 240 | M48: =IF((G48+I48)>0,60/(G48+I48),0)*$M$12 -> 150 | N48: =($G48+$I48)/$L$135 -> 0.31858548
...

Sheet Lay out
B1: LINE LAYOUT | E1: CONCORD APPAREL (PVT) LTD.
E2: BLOCK A0, SEETHAWAKA INDUSTRIAL PARK, AVISSAWELLA, SRI LANKA.
E3: TEL : 036-2265000
B5: IE OFFICER | E5: NAWAM
B7: MO : | E7: 26 | Q7: SMV | T7: 49.3
B8: TEAM: | E8: 8 | Q8: PLANNED EFF% | T8: 0.75
B9: STYLE | E9: 3801 | Q9: PLANNED TARGET PER HOUR | T9: =IFERROR(((E7*60/T7)*T8),"") -> 23.732252
B10: DESCRIPTION | E10: JACKET | Q10: TACK TIME | T10: =T7/E7 -> 1.8961538
B13: =IFERROR(VLOOKUP(C13,OB!$B$1:$N$131,4,FALSE),"") | D13: =IFERROR(VLOOKUP(C13,OB!$B$1:$N$131,2,FALSE),"") | F13: =IFERROR(VLOOKUP(C13,OB!$B$1:$N$131,6,FALSE),"") | G13: =SUM(F13:F18) -> 0 | Q13: =IFERROR(VLOOKUP(R13,OB!$B$1:$N$131,4,FALSE),"") | S13: =IFERROR(VLOOKUP(R13,OB!$B$1:$N$131,2,FALSE),"") | U13: =IFERROR(VLOOKUP(R13,OB!$B$1:$N$131,6,FALSE),"") | V13: =SUM(U13:U18) -> 0
B14: =IFERROR(VLOOKUP(C14,OB!$B$1:$N$131,4,FALSE),"") | D14: =IFERROR(VLOOKUP(C14,OB!$B$1:$N$131,2,FALSE),"") | F14: =IFERROR(VLOOKUP(C14,OB!$B$1:$N$131,6,FALSE),"") | G14: =IFERROR(60/G13,"") | Q14: =IFERROR(VLOOKUP(R14,OB!$B$1:$N$131,4,FALSE),"") | S14: =IFERROR(VLOOKUP(R14,OB!$B$1:$N$131,2,FALSE),"") | U14: =IFERROR(VLOOKUP(R14,OB!$B$1:$N$131,6,FALSE),"") | V14: =IFERROR(60/V13,"")
B15: =IFERROR(VLOOKUP(C15,OB!$B$1:$N$131,4,FALSE),"") | C15: H19 | D15: =IFERROR(VLOOKUP(C15,OB!$B$1:$N$131,2,FALSE),"") | F15: =IFERROR(VLOOKUP(C15,OB!$B$1:$N$131,6,FALSE),"") | Q15: =IFERROR(VLOOKUP(R15,OB!$B$1:$N$131,4,FALSE),"") | R15: H19 | S15: =IFERROR(VLOOKUP(R15,OB!$B$1:$N$131,2,FALSE),"") | U15: =IFERROR(VLOOKUP(R15,OB!$B$1:$N$131,6,FALSE),"")
B16: =IFERROR(VLOOKUP(C16,OB!$B$1:$N$131,4,FALSE),"") | D16: =IFERROR(VLOOKUP(C16,OB!$B$1:$N$131,2,FALSE),"") | F16: =IFERROR(VLOOKUP(C16,OB!$B$1:$N$131,6,FALSE),"") | Q16: =IFERROR(VLOOKUP(R16,OB!$B$1:$N$131,4,FALSE),"") | S16: =IFERROR(VLOOKUP(R16,OB!$B$1:$N$131,2,FALSE),"") | U16: =IFERROR(VLOOKUP(R16,OB!$B$1:$N$131,6,FALSE),"")
B17: =IFERROR(VLOOKUP(C17,OB!$B$1:$N$131,4,FALSE),"") | D17: =IFERROR(VLOOKUP(C17,OB!$B$1:$N$131,2,FALSE),"") | F17: =IFERROR(VLOOKUP(C17,OB!$B$1:$N$131,6,FALSE),"") | G17: =IFERROR(G13/$T$10,"") -> 0 | Q17: =IFERROR(VLOOKUP(R17,OB!$B$1:$N$131,4,FALSE),"") | S17: =IFERROR(VLOOKUP(R17,OB!$B$1:$N$131,2,FALSE),"") | U17: =IFERROR(VLOOKUP(R17,OB!$B$1:$N$131,6,FALSE),"") | V17: =IFERROR(V13/$T$10,"") -> 0
B18: =IFERROR(VLOOKUP(C18,OB!$B$1:$N$131,4,FALSE),"") | D18: =IFERROR(VLOOKUP(C18,OB!$B$1:$N$131,2,FALSE),"") | F18: =IFERROR(VLOOKUP(C18,OB!$B$1:$N$131,6,FALSE),"") | Q18: =IFERROR(VLOOKUP(R18,OB!$B$1:$N$131,4,FALSE),"") | S18: =IFERROR(VLOOKUP(R18,OB!$B$1:$N$131,2,FALSE),"") | U18: =IFERROR(VLOOKUP(R18,OB!$B$1:$N$131,6,FALSE),"")
B20: =IFERROR(VLOOKUP(C20,OB!$B$1:$N$131,4,FALSE),"") | D20: =IFERROR(VLOOKUP(C20,OB!$B$1:$N$131,2,FALSE),"") | F20: =IFERROR(VLOOKUP(C20,OB!$B$1:$N$131,6,FALSE),"") | G20: =SUM(F20:F25) -> 0 | Q20: =IFERROR(VLOOKUP(R20,OB!$B$1:$N$131,4,FALSE),"") | S20: =IFERROR(VLOOKUP(R20,OB!$B$1:$N$131,2,FALSE),"") | U20: =IFERROR(VLOOKUP(R20,OB!$B$1:$N$131,6,FALSE),"") | V20: =SUM(U20:U25) -> 0.24
B21: =IFERROR(VLOOKUP(C21,OB!$B$1:$N$131,4,FALSE),"") | D21: =IFERROR(VLOOKUP(C21,OB!$B$1:$N$131,2,FALSE),"") | F21: =IFERROR(VLOOKUP(C21,OB!$B$1:$N$131,6,FALSE),"") | G21: =IFERROR(60/G20,"") | Q21: =IFERROR(VLOOKUP(R21,OB!$B$1:$N$131,4,FALSE),"") -> SN | R21: 38 | S21: =IFERROR(VLOOKUP(R21,OB!$B$1:$N$131,2,FALSE),"") -> BACK WELT PKT BAG TACK TO TOP EDGE *2 | U21: =IFERROR(VLOOKUP(R21,OB!$B$1:$N$131,6,FALSE),"") -> 0.24 | V21: =IFERROR(60/V20,"") -> 250
B22: =IFERROR(VLOOKUP(C22,OB!$B$1:$N$131,4,FALSE),"") | C22: H18 | D22: =IFERROR(VLOOKUP(C22,OB!$B$1:$N$131,2,FALSE),"") | F22: =IFERROR(VLOOKUP(C22,OB!$B$1:$N$131,6,FALSE),"") | Q22: =IFERROR(VLOOKUP(R22,OB!$B$1:$N$131,4,FALSE),"") | R22: 107 | S22: =IFERROR(VLOOKUP(R22,OB!$B$1:$N$131,2,FALSE),"") | U22: =IFERROR(VLOOKUP(R22,OB!$B$1:$N$131,6,FALSE),"")
B23: =IFERROR(VLOOKUP(C23,OB!$B$1:$N$131,4,FALSE),"") | D23: =IFERROR(VLOOKUP(C23,OB!$B$1:$N$131,2,FALSE),"") | F23: =IFERROR(VLOOKUP(C23,OB!$B$1:$N$131,6,FALSE),"") | Q23: =IFERROR(VLOOKUP(R23,OB!$B$1:$N$131,4,FALSE),"") | R23: 108 | S23: =IFERROR(VLOOKUP(R23,OB!$B$1:$N$131,2,FALSE),"") | U23: =IFERROR(VLOOKUP(R23,OB!$B$1:$N$131,6,FALSE),"")
B24: =IFERROR(VLOOKUP(C24,OB!$B$1:$N$131,4,FALSE),"") | D24: =IFERROR(VLOOKUP(C24,OB!$B$1:$N$131,2,FALSE),"") | F24: =IFERROR(VLOOKUP(C24,OB!$B$1:$N$131,6,FALSE),"") | G24: =IFERROR(G20/$T$10,"") -> 0 | Q24: =IFERROR(VLOOKUP(R24,OB!$B$1:$N$131,4,FALSE),"") | R24: B1 | S24: =IFERROR(VLOOKUP(R24,OB!$B$1:$N$131,2,FALSE),"") | U24: =IFERROR(VLOOKUP(R24,OB!$B$1:$N$131,6,FALSE),"") | V24: =IFERROR(V20/$T$10,"") -> 0.12657201
B25: =IFERROR(VLOOKUP(C25,OB!$B$1:$N$131,4,FALSE),"") | D25: =IFERROR(VLOOKUP(C25,OB!$B$1:$N$131,2,FALSE),"") | F25: =IFERROR(VLOOKUP(C25,OB!$B$1:$N$131,6,FALSE),"") | Q25: =IFERROR(VLOOKUP(R25,OB!$B$1:$N$131,4,FALSE),"") | S25: =IFERROR(VLOOKUP(R25,OB!$B$1:$N$131,2,FALSE),"") | U25: =IFERROR(VLOOKUP(R25,OB!$B$1:$N$131,6,FALSE),"")
B27: =IFERROR(VLOOKUP(C27,OB!$B$1:$N$131,4,FALSE),"") | D27: =IFERROR(VLOOKUP(C27,OB!$B$1:$N$131,2,FALSE),"") | F27: =IFERROR(VLOOKUP(C27,OB!$B$1:$N$131,6,FALSE),"") | G27: =SUM(F27:F32) -> 0 | Q27: =IFERROR(VLOOKUP(R27,OB!$B$1:$N$131,4,FALSE),"") | S27: =IFERROR(VLOOKUP(R27,OB!$B$1:$N$131,2,FALSE),"") | U27: =IFERROR(VLOOKUP(R27,OB!$B$1:$N$131,6,FALSE),"") | V27: =SUM(U27:U32) -> 0.44
B28: =IFERROR(VLOOKUP(C28,OB!$B$1:$N$131,4,FALSE),"") | C28: 101 | D28: =IFERROR(VLOOKUP(C28,OB!$B$1:$N$131,2,FALSE),"") | F28: =IFERROR(VLOOKUP(C28,OB!$B$1:$N$131,6,FALSE),"") | G28: =IFERROR(60/G27,"") | Q28: =IFERROR(VLOOKUP(R28,OB!$B$1:$N$131,4,FALSE),"") | R28: 102 | S28: =IFERROR(VLOOKUP(R28,OB!$B$1:$N$131,2,FALSE),"") | U28: =IFERROR(VLOOKUP(R28,OB!$B$1:$N$131,6,FALSE),"") | V28: =IFERROR(60/V27,"") -> 136.36364
B29: =IFERROR(VLOOKUP(C29,OB!$B$1:$N$131,4,FALSE),"") | C29: 103 | D29: =IFERROR(VLOOKUP(C29,OB!$B$1:$N$131,2,FALSE),"") | F29: =IFERROR(VLOOKUP(C29,OB!$B$1:$N$131,6,FALSE),"") | Q29: =IFERROR(VLOOKUP(R29,OB!$B$1:$N$131,4,FALSE),"") | R29: 105 | S29: =IFERROR(VLOOKUP(R29,OB!$B$1:$N$131,2,FALSE),"") | U29: =IFERROR(VLOOKUP(R29,OB!$B$1:$N$131,6,FALSE),"")
B30: =IFERROR(VLOOKUP(C30,OB!$B$1:$N$131,4,FALSE),"") | C30: 106 | D30: =IFERROR(VLOOKUP(C30,OB!$B$1:$N$131,2,FALSE),"") | F30: =IFERROR(VLOOKUP(C30,OB!$B$1:$N$131,6,FALSE),"") | Q30: =IFERROR(VLOOKUP(R30,OB!$B$1:$N$131,4,FALSE),"") -> SN | R30: 2 | S30: =IFERROR(VLOOKUP(R30,OB!$B$1:$N$131,2,FALSE),"") -> IN SIDE COIN PKT ATTACH *1 | U30: =IFERROR(VLOOKUP(R30,OB!$B$1:$N$131,6,FALSE),"") -> 0.28
B31: =IFERROR(VLOOKUP(C31,OB!$B$1:$N$131,4,FALSE),"") | D31: =IFERROR(VLOOKUP(C31,OB!$B$1:$N$131,2,FALSE),"") | F31: =IFERROR(VLOOKUP(C31,OB!$B$1:$N$131,6,FALSE),"") | G31: =IFERROR(G27/$T$10,"") -> 0 | Q31: =IFERROR(VLOOKUP(R31,OB!$B$1:$N$131,4,FALSE),"") -> SN | R31: 3 | S31: =IFERROR(VLOOKUP(R31,OB!$B$1:$N$131,2,FALSE),"") -> SIDE ZIPPER EDEG TACK *2 | U31: =IFERROR(VLOOKUP(R31,OB!$B$1:$N$131,6,FALSE),"") -> 0.16 | V31: =IFERROR(V27/$T$10,"") -> 0.23204868
B32: =IFERROR(VLOOKUP(C32,OB!$B$1:$N$131,4,FALSE),"") | D32: =IFERROR(VLOOKUP(C32,OB!$B$1:$N$131,2,FALSE),"") | F32: =IFERROR(VLOOKUP(C32,OB!$B$1:$N$131,6,FALSE),"") | Q32: =IFERROR(VLOOKUP(R32,OB!$B$1:$N$131,4,FALSE),"") | S32: =IFERROR(VLOOKUP(R32,OB!$B$1:$N$131,2,FALSE),"") | U32: =IFERROR(VLOOKUP(R32,OB!$B$1:$N$131,6,FALSE),"")
B34: =IFERROR(VLOOKUP(C34,OB!$B$1:$N$131,4,FALSE),"") | D34: =IFERROR(VLOOKUP(C34,OB!$B$1:$N$131,2,FALSE),"") | F34: =IFERROR(VLOOKUP(C34,OB!$B$1:$N$131,6,FALSE),"") | G34: =SUM(F34:F39) -> 0.86 | Q34: =IFERROR(VLOOKUP(R34,OB!$B$1:$N$131,4,FALSE),"") | S34: =IFERROR(VLOOKUP(R34,OB!$B$1:$N$131,2,FALSE),"") | U34: =IFERROR(VLOOKUP(R34,OB!$B$1:$N$131,6,FALSE),"") | V34: =SUM(U34:U39) -> 0
B35: =IFERROR(VLOOKUP(C35,OB!$B$1:$N$131,4,FALSE),"") -> SN | C35: 4 | D35: =IFERROR(VLOOKUP(C35,OB!$B$1:$N$131,2,FALSE),"") -> SIDE ZIPPER PKT BAG FACIN ATTACH *1 | F35: =IFERROR(VLOOKUP(C35,OB!$B$1:$N$131,6,FALSE),"") -> 0.22 | G35: =IFERROR(60/G34,"") -> 69.767442 | Q35: =IFERROR(VLOOKUP(R35,OB!$B$1:$N$131,4,FALSE),"") | S35: =IFERROR(VLOOKUP(R35,OB!$B$1:$N$131,2,FALSE),"") | U35: =IFERROR(VLOOKUP(R35,OB!$B$1:$N$131,6,FALSE),"") | V35: =IFERROR(60/V34,"")
B36: =IFERROR(VLOOKUP(C36,OB!$B$1:$N$131,4,FALSE),"") -> SN | C36: 3 | D36: =IFERROR(VLOOKUP(C36,OB!$B$1:$N$131,2,FALSE),"") -> SIDE ZIPPER EDEG TACK *2 | F36: =IFERROR(VLOOKUP(C36,OB!$B$1:$N$131,6,FALSE),"") -> 0.16 | Q36: =IFERROR(VLOOKUP(R36,OB!$B$1:$N$131,4,FALSE),"") | R36: 95 | S36: =IFERROR(VLOOKUP(R36,OB!$B$1:$N$131,2,FALSE),"") | U36: =IFERROR(VLOOKUP(R36,OB!$B$1:$N$131,6,FALSE),"")
B37: =IFERROR(VLOOKUP(C37,OB!$B$1:$N$131,4,FALSE),"") -> SN | C37: 2 | D37: =IFERROR(VLOOKUP(C37,OB!$B$1:$N$131,2,FALSE),"") -> IN SIDE COIN PKT ATTACH *1 | F37: =IFERROR(VLOOKUP(C37,OB!$B$1:$N$131,6,FALSE),"") -> 0.28 | Q37: =IFERROR(VLOOKUP(R37,OB!$B$1:$N$131,4,FALSE),"") | R37: 96 | S37: =IFERROR(VLOOKUP(R37,OB!$B$1:$N$131,2,FALSE),"") | U37: =IFERROR(VLOOKUP(R37,OB!$B$1:$N$131,6,FALSE),"")
B38: =IFERROR(VLOOKUP(C38,OB!$B$1:$N$131,4,FALSE),"") -> SN | C38: 1 | D38: =IFERROR(VLOOKUP(C38,OB!$B$1:$N$131,2,FALSE),"") -> IN SIDE COIN PKT HEM *1 | F38: =IFERROR(VLOOKUP(C38,OB!$B$1:$N$131,6,FALSE),"") -> 0.2 | G38: =IFERROR(G34/$T$10,"") -> 0.4535497 | Q38: =IFERROR(VLOOKUP(R38,OB!$B$1:$N$131,4,FALSE),"") | S38: =IFERROR(VLOOKUP(R38,OB!$B$1:$N$131,2,FALSE),"") | U38: =IFERROR(VLOOKUP(R38,OB!$B$1:$N$131,6,FALSE),"") | V38: =IFERROR(V34/$T$10,"") -> 0
B39: =IFERROR(VLOOKUP(C39,OB!$B$1:$N$131,4,FALSE),"") | D39: =IFERROR(VLOOKUP(C39,OB!$B$1:$N$131,2,FALSE),"") | F39: =IFERROR(VLOOKUP(C39,OB!$B$1:$N$131,6,FALSE),"") | Q39: =IFERROR(VLOOKUP(R39,OB!$B$1:$N$131,4,FALSE),"") | S39: =IFERROR(VLOOKUP(R39,OB!$B$1:$N$131,2,FALSE),"") | U39: =IFERROR(VLOOKUP(R39,OB!$B$1:$N$131,6,FALSE),"")
B41: =IFERROR(VLOOKUP(C41,OB!$B$1:$N$131,4,FALSE),"") | D41: =IFERROR(VLOOKUP(C41,OB!$B$1:$N$131,2,FALSE),"") | F41: =IFERROR(VLOOKUP(C41,OB!$B$1:$N$131,6,FALSE),"") | G41: =SUM(F41:F47) -> 0 | Q41: =IFERROR(VLOOKUP(R41,OB!$B$1:$N$131,4,FALSE),"") | S41: =IFERROR(VLOOKUP(R41,OB!$B$1:$N$131,2,FALSE),"") | U41: =IFERROR(VLOOKUP(R41,OB!$B$1:$N$131,6,FALSE),"") | V41: =SUM(U41:U47) -> 0
B42: =IFERROR(VLOOKUP(C42,OB!$B$1:$N$131,4,FALSE),"") | D42: =IFERROR(VLOOKUP(C42,OB!$B$1:$N$131,2,FALSE),"") | F42: =IFERROR(VLOOKUP(C42,OB!$B$1:$N$131,6,FALSE),"") | G42: =IFERROR(60/G41,"") | Q42: =IFERROR(VLOOKUP(R42,OB!$B$1:$N$131,4,FALSE),"") | S42: =IFERROR(VLOOKUP(R42,OB!$B$1:$N$131,2,FALSE),"") | U42: =IFERROR(VLOOKUP(R42,OB!$B$1:$N$131,6,FALSE),"") | V42: =IFERROR(60/V41,"")
B43: =IFERROR(VLOOKUP(C43,OB!$B$1:$N$131,4,FALSE),"") | C43: 98 | D43: =IFERROR(VLOOKUP(C43,OB!$B$1:$N$131,2,FALSE),"") | F43: =IFERROR(VLOOKUP(C43,OB!$B$1:$N$131,6,FALSE),"") | Q43: =IFERROR(VLOOKUP(R43,OB!$B$1:$N$131,4,FALSE),"") | R43: 78 | S43: =IFERROR(VLOOKUP(R43,OB!$B$1:$N$131,2,FALSE),"") | U43: =IFERROR(VLOOKUP(R43,OB!$B$1:$N$131,6,FALSE),"")
B44: =IFERROR(VLOOKUP(C44,OB!$B$1:$N$131,4,FALSE),"") | C44: H12 | D44: =IFERROR(VLOOKUP(C44,OB!$B$1:$N$131,2,FALSE),"") | F44: =IFERROR(VLOOKUP(C44,OB!$B$1:$N$131,6,FALSE),"") | Q44: =IFERROR(VLOOKUP(R44,OB!$B$1:$N$131,4,FALSE),"") | S44: =IFERROR(VLOOKUP(R44,OB!$B$1:$N$131,2,FALSE),"") | U44: =IFERROR(VLOOKUP(R44,OB!$B$1:$N$131,6,FALSE),"")
B45: =IFERROR(VLOOKUP(C45,OB!$B$1:$N$131,4,FALSE),"") | D45: =IFERROR(VLOOKUP(C45,OB!$B$1:$N$131,2,FALSE),"") | F45: =IFERROR(VLOOKUP(C45,OB!$B$1:$N$131,6,FALSE),"") | Q45: =IFERROR(VLOOKUP(R45,OB!$B$1:$N$131,4,FALSE),"") | S45: =IFERROR(VLOOKUP(R45,OB!$B$1:$N$131,2,FALSE),"") | U45: =IFERROR(VLOOKUP(R45,OB!$B$1:$N$131,6,FALSE),"")
B46: =IFERROR(VLOOKUP(C46,OB!$B$1:$N$131,4,FALSE),"") | D46: =IFERROR(VLOOKUP(C46,OB!$B$1:$N$131,2,FALSE),"") | F46: =IFERROR(VLOOKUP(C46,OB!$B$1:$N$131,6,FALSE),"") | G46: =IFERROR(G41/$T$10,"") -> 0 | Q46: =IFERROR(VLOOKUP(R46,OB!$B$1:$N$131,4,FALSE),"") | S46: =IFERROR(VLOOKUP(R46,OB!$B$1:$N$131,2,FALSE),"") | U46: =IFERROR(VLOOKUP(R46,OB!$B$1:$N$131,6,FALSE),"") | V46: =IFERROR(V41/$T$10,"") -> 0
B47: =IFERROR(VLOOKUP(C47,OB!$B$1:$N$131,4,FALSE),"") | D47: =IFERROR(VLOOKUP(C47,OB!$B$1:$N$131,2,FALSE),"") | F47: =IFERROR(VLOOKUP(C47,OB!$B$1:$N$131,6,FALSE),"") | Q47: =IFERROR(VLOOKUP(R47,OB!$B$1:$N$131,4,FALSE),"") | S47: =IFERROR(VLOOKUP(R47,OB!$B$1:$N$131,2,FALSE),"") | U47: =IFERROR(VLOOKUP(R47,OB!$B$1:$N$131,6,FALSE),"")
B49: =IFERROR(VLOOKUP(C49,OB!$B$1:$N$131,4,FALSE),"") | D49: =IFERROR(VLOOKUP(C49,OB!$B$1:$N$131,2,FALSE),"") | F49: =IFERROR(VLOOKUP(C49,OB!$B$1:$N$131,6,FALSE),"") | G49: =SUM(F49:F54) -> 0 | Q49: =IFERROR(VLOOKUP(R49,OB!$B$1:$N$131,4,FALSE),"") | S49: =IFERROR(VLOOKUP(R49,OB!$B$1:$N$131,2,FALSE),"") | U49: =IFERROR(VLOOKUP(R49,OB!$B$1:$N$131,6,FALSE),"") | V49: =SUM(U49:U54) -> 0
...

Sheet Feeding plan
B1: Date | C1: ----------------------- | D1: Line feeding analysis report
B2: Line :-
B3: Style :-
A4: No | B4: EPF | C4: Name | D4: Operation | E4: M/C | F4: Planned time (Min) | G4: Start time | H4: End time | I4: Duration | J4: Variation | K4: Sup | L4: Q/C | M4: Mac | N4: Remarks
A5: =IF('Lay out'!#REF!="","",'Lay out'!#REF!) -> #REF!
A10: =IF('Lay out'!#REF!="","",'Lay out'!#REF!) -> #REF!
A15: ='Lay out'!A156 -> 0
A20: ='Lay out'!W156 -> 0
A25: ='Lay out'!A149 -> 0
A30: ='Lay out'!W149 -> 0
A35: ='Lay out'!A142 -> 0
A40: ='Lay out'!W142 -> 0
A45: ='Lay out'!A135 -> 0
A50: ='Lay out'!W135 -> 0
A55: ='Lay out'!A128 -> 0
A60: ='Lay out'!W128 -> 0
A65: =IF('Lay out'!A217="","",'Lay out'!A217)
A70: =IF('Lay out'!A222="","",'Lay out'!A222)
A75: =IF('Lay out'!A227="","",'Lay out'!A227)
A80: =IF('Lay out'!A232="","",'Lay out'!A232)
A85: =IF('Lay out'!A237="","",'Lay out'!A237)
A90: =IF('Lay out'!A242="","",'Lay out'!A242)
A95: =IF('Lay out'!A247="","",'Lay out'!A247)
A100: =IF('Lay out'!A252="","",'Lay out'!A252)
A105: =IF('Lay out'!A257="","",'Lay out'!A257)
A110: =IF('Lay out'!A262="","",'Lay out'!A262)
A115: =IF('Lay out'!A267="","",'Lay out'!A267)
A120: =IF('Lay out'!A272="","",'Lay out'!A272)
... A510: =IF('Lay out'!A662="","",'Lay out'!A662)
F515: =SUM(F5:F514) -> 0
D517: ---------------------------------- | E517: -------------------------- | H517: -------------------------- | K517: -------------------------- | N517: --------------------------
D518: IE Officer | E518: Pro Executive | H518: QA manager | K518: IE Manager | N518: Factrory manager

Sheet Capacity graph
C1: Capacity Graph
A3: EPF | B3: Name | C3: Operation | D3: M/C | E3: SMV | F3: Total SMV | G3: Cycle time (Sec.) | L3: Avg. (Min) | M3: Total (Min) | N3: with allw. 10% (Min) | O3: Hourly Pieces Capacity | P3: Eff % | Q3: Remarks
G4: 1 | H4: 2 | I4: 3 | J4: 4 | K4: 5
F5: =SUM(E5:E10) -> 0.9 | L5: =IFERROR(AVERAGE(G5:K5)/60,"") | M5: =SUM(L5:L10) -> 1.05 | N5: =IFERROR(M5*1.1,"") -> 1.155 | O5: =IFERROR(60/N5,"") -> 51.948052 | P5: =IFERROR(SUM(E5:E10)*O5/60,"") -> 0.77922078
E6: 0.2 | L6: 0.25
E7: 0.5 | L7: 0.3
L8: 0.4
E9: 0.2 | L9: 0.1
L10: =IFERROR(AVERAGE(G10:K10)/60,"")
F11: =SUM(E11:E16) -> 0 | L11: =IFERROR(AVERAGE(G11:K11)/60,"") | M11: =SUM(L11:L16) -> 0 | N11: =IFERROR(M11*1.1,"") -> 0 | O11: =IFERROR(60/N11,"") | P11: =IFERROR(SUM(E11:E16)*O11/60,"")
L12: =IFERROR(AVERAGE(G12:K12)/60,"")
L13: =IFERROR(AVERAGE(G13:K13)/60,"")
L14: =IFERROR(AVERAGE(G14:K14)/60,"")
L15: =IFERROR(AVERAGE(G15:K15)/60,"")
L16: =IFERROR(AVERAGE(G16:K16)/60,"")
F17: =SUM(E17:E22) -> 0 | L17: =IFERROR(AVERAGE(G17:K17)/60,"") | M17: =SUM(L17:L22) -> 0 | N17: =IFERROR(M17*1.1,"") -> 0 | O17: =IFERROR(60/N17,"") | P17: =IFERROR(SUM(E17:E22)*O17/60,"")
L18: =IFERROR(AVERAGE(G18:K18)/60,"")
L19: =IFERROR(AVERAGE(G19:K19)/60,"")
L20: =IFERROR(AVERAGE(G20:K20)/60,"")
L21: =IFERROR(AVERAGE(G21:K21)/60,"")
L22: =IFERROR(AVERAGE(G22:K22)/60,"")
F23: =SUM(E23:E28) -> 0 | L23: =IFERROR(AVERAGE(G23:K23)/60,"") | M23: =SUM(L23:L28) -> 0 | N23: =IFERROR(M23*1.1,"") -> 0 | O23: =IFERROR(60/N23,"") | P23: =IFERROR(SUM(E23:E28)*O23/60,"")
L24: =IFERROR(AVERAGE(G24:K24)/60,"")
L25: =IFERROR(AVERAGE(G25:K25)/60,"")
L26: =IFERROR(AVERAGE(G26:K26)/60,"")
L27: =IFERROR(AVERAGE(G27:K27)/60,"")
L28: =IFERROR(AVERAGE(G28:K28)/60,"")
F29: =SUM(E29:E34) -> 0 | L29: =IFERROR(AVERAGE(G29:K29)/60,"") | M29: =SUM(L29:L34) -> 0 | N29: =IFERROR(M29*1.1,"") -> 0 | O29: =IFERROR(60/N29,"") | P29: =IFERROR(SUM(E29:E34)*O29/60,"")
L30: =IFERROR(AVERAGE(G30:K30)/60,"")
L31: =IFERROR(AVERAGE(G31:K31)/60,"")
L32: =IFERROR(AVERAGE(G32:K32)/60,"")
L33: =IFERROR(AVERAGE(G33:K33)/60,"")
L34: =IFERROR(AVERAGE(G34:K34)/60,"")
F35: =SUM(E35:E40) -> 0 | L35: =IFERROR(AVERAGE(G35:K35)/60,"") | M35: =SUM(L35:L40) -> 0 | N35: =IFERROR(M35*1.1,"") -> 0 | O35: =IFERROR(60/N35,"") | P35: =IFERROR(SUM(E35:E40)*O35/60,"")
L36: =IFERROR(AVERAGE(G36:K36)/60,"")
L37: =IFERROR(AVERAGE(G37:K37)/60,"")
L38: =IFERROR(AVERAGE(G38:K38)/60,"")
L39: =IFERROR(AVERAGE(G39:K39)/60,"")
L40: =IFERROR(AVERAGE(G40:K40)/60,"")
F41: =SUM(E41:E46) -> 0 | L41: =IFERROR(AVERAGE(G41:K41)/60,"") | M41: =SUM(L41:L46) -> 0 | N41: =IFERROR(M41*1.1,"") -> 0 | O41: =IFERROR(60/N41,"") | P41: =IFERROR(SUM(E41:E46)*O41/60,"")
...

Sheet Bar chart
B2: EPF | C2: Name | D2: Capacity (Pieces) | E2: Eff%
B3: ='Capacity graph'!A5 -> 0 | C3: ='Capacity graph'!B5 -> 0 | D3: 54
B4: ='Capacity graph'!A11 -> 0 | C4: ='Capacity graph'!B11 -> 0 | D4: 80
B5: ='Capacity graph'!A17 -> 0 | C5: ='Capacity graph'!B17 -> 0 | D5: 77 | E5: ='Capacity graph'!P17
B6: ='Capacity graph'!A23 -> 0 | C6: ='Capacity graph'!B23 -> 0 | D6: 60 | E6: ='Capacity graph'!P23
B7: ='Capacity graph'!A29 -> 0 | C7: ='Capacity graph'!B29 -> 0 | D7: 43 | E7: ='Capacity graph'!P29
B8: ='Capacity graph'!A35 -> 0 | C8: ='Capacity graph'!B35 -> 0 | D8: 44 | E8: ='Capacity graph'!P35
B9: ='Capacity graph'!A41 -> 0 | C9: ='Capacity graph'!B41 -> 0 | D9: 42 | E9: ='Capacity graph'!P41
B10: ='Capacity graph'!A47 -> 0 | C10: ='Capacity graph'!B47 -> 0 | D10: ='Capacity graph'!O47 | E10: ='Capacity graph'!P47
B11: ='Capacity graph'!A53 -> 0 | C11: ='Capacity graph'!B53 -> 0 | D11: ='Capacity graph'!O53 | E11: ='Capacity graph'!P53
B12: ='Capacity graph'!A59 -> 0 | C12: ='Capacity graph'!B59 -> 0 | D12: ='Capacity graph'!O59 | E12: ='Capacity graph'!P59
B13: ='Capacity graph'!A65 -> 0 | C13: ='Capacity graph'!B65 -> 0 | D13: ='Capacity graph'!O65 | E13: ='Capacity graph'!P65
B14: ='Capacity graph'!A71 -> 0 | C14: ='Capacity graph'!B71 -> 0 | D14: ='Capacity graph'!O71 | E14: ='Capacity graph'!P71
B15: ='Capacity graph'!A77 -> 0 | C15: ='Capacity graph'!B77 -> 0 | D15: ='Capacity graph'!O77 | E15: ='Capacity graph'!P77
B16: ='Capacity graph'!A83 -> 0 | C16: ='Capacity graph'!B83 -> 0 | D16: ='Capacity graph'!O83 | E16: ='Capacity graph'!P83
B17: ='Capacity graph'!A89 -> 0 | C17: ='Capacity graph'!B89 -> 0 | D17: ='Capacity graph'!O89 | E17: ='Capacity graph'!P89
B18: ='Capacity graph'!A95 -> 0 | C18: ='Capacity graph'!B95 -> 0 | D18: ='Capacity graph'!O95 | E18: ='Capacity graph'!P95
B19: ='Capacity graph'!A101 -> 0 | C19: ='Capacity graph'!B101 -> 0 | D19: ='Capacity graph'!O101 | E19: ='Capacity graph'!P101
B20: ='Capacity graph'!A107 -> 0 | C20: ='Capacity graph'!B107 -> 0 | D20: ='Capacity graph'!O107 | E20: ='Capacity graph'!P107
B21: ='Capacity graph'!A113 -> 0 | C21: ='Capacity graph'!B113 -> 0 | D21: ='Capacity graph'!O113 | E21: ='Capacity graph'!P113
B22: ='Capacity graph'!A119 -> 0 | C22: ='Capacity graph'!B119 -> 0 | D22: ='Capacity graph'!O119 | E22: ='Capacity graph'!P119
B23: ='Capacity graph'!A125 -> 0 | C23: ='Capacity graph'!B125 -> 0 | D23: ='Capacity graph'!O125 | E23: ='Capacity graph'!P125
B24: ='Capacity graph'!A131 -> 0 | C24: ='Capacity graph'!B131 -> 0 | D24: ='Capacity graph'!O131 | E24: ='Capacity graph'!P131
B25: ='Capacity graph'!A137 -> 0 | C25: ='Capacity graph'!B137 -> 0 | D25: ='Capacity graph'!O137 | E25: ='Capacity graph'!P137
B26: ='Capacity graph'!A143 -> 0 | C26: ='Capacity graph'!B143 -> 0 | D26: ='Capacity graph'!O143 | E26: ='Capacity graph'!P143
B27: ='Capacity graph'!A149 -> 0 | C27: ='Capacity graph'!B149 -> 0 | D27: ='Capacity graph'!O149 | E27: ='Capacity graph'!P149
B28: ='Capacity graph'!A155 -> 0 | C28: ='Capacity graph'!B155 -> 0 | D28: ='Capacity graph'!O155 | E28: ='Capacity graph'!P155
B29: ='Capacity graph'!A161 -> 0 | C29: ='Capacity graph'!B161 -> 0 | D29: ='Capacity graph'!O161 | E29: ='Capacity graph'!P161
B30: ='Capacity graph'!A167 -> 0 | C30: ='Capacity graph'!B167 -> 0 | D30: ='Capacity graph'!O167 | E30: ='Capacity graph'!P167
B31: ='Capacity graph'!A173 -> 0 | C31: ='Capacity graph'!B173 -> 0 | D31: ='Capacity graph'!O173 | E31: ='Capacity graph'!P173
B32: ='Capacity graph'!A179 -> 0 | C32: ='Capacity graph'!B179 -> 0 | D32: ='Capacity graph'!O179 | E32: ='Capacity graph'!P179
B33: ='Capacity graph'!A185 -> 0 | C33: ='Capacity graph'!B185 -> 0 | D33: ='Capacity graph'!O185 | E33: ='Capacity graph'!P185
B34: ='Capacity graph'!A191 -> 0 | C34: ='Capacity graph'!B191 -> 0 | D34: ='Capacity graph'!O191 | E34: ='Capacity graph'!P191
B35: ='Capacity graph'!A197 -> 0 | C35: ='Capacity graph'!B197 -> 0 | D35: ='Capacity graph'!O197 | E35: ='Capacity graph'!P197
B36: ='Capacity graph'!A203 -> 0 | C36: ='Capacity graph'!B203 -> 0 | D36: ='Capacity graph'!O203 | E36: ='Capacity graph'!P203
B37: ='Capacity graph'!A209 -> 0 | C37: ='Capacity graph'!B209 -> 0 | D37: ='Capacity graph'!O209 | E37: ='Capacity graph'!P209
B38: ='Capacity graph'!A215 -> 0 | C38: ='Capacity graph'!B215 -> 0 | D38: ='Capacity graph'!O215 | E38: ='Capacity graph'!P215
B39: ='Capacity graph'!A221 -> 0 | C39: ='Capacity graph'!B221 -> 0 | D39: ='Capacity graph'!O221 | E39: ='Capacity graph'!P221
B40: ='Capacity graph'!A227 -> 0 | C40: ='Capacity graph'!B227 -> 0 | D40: ='Capacity graph'!O227 | E40: ='Capacity graph'!P227
B41: ='Capacity graph'!A233 -> 0 | C41: ='Capacity graph'!B233 -> 0 | D41: ='Capacity graph'!O233 | E41: ='Capacity graph'!P233
...
